[2021-04-23 17:08:52,309] {taskinstance.py:851} INFO - Dependencies all met for <TaskInstance: ks-3-example_kubernetes_pod.task-one 2019-01-01T00:00:00+00:00 [queued]>
[2021-04-23 17:08:52,327] {taskinstance.py:851} INFO - Dependencies all met for <TaskInstance: ks-3-example_kubernetes_pod.task-one 2019-01-01T00:00:00+00:00 [queued]>
[2021-04-23 17:08:52,328] {taskinstance.py:1042} INFO - 
--------------------------------------------------------------------------------
[2021-04-23 17:08:52,329] {taskinstance.py:1043} INFO - Starting attempt 1 of 2
[2021-04-23 17:08:52,330] {taskinstance.py:1044} INFO - 
--------------------------------------------------------------------------------
[2021-04-23 17:08:52,337] {taskinstance.py:1063} INFO - Executing <Task(KubernetesPodOperator): task-one> on 2019-01-01T00:00:00+00:00
[2021-04-23 17:08:52,344] {standard_task_runner.py:76} INFO - Running: ['airflow', 'tasks', 'run', 'ks-3-example_kubernetes_pod', 'task-one', '2019-01-01T00:00:00+00:00', '--job-id', '814', '--pool', 'default_pool', '--raw', '--subdir', 'DAGS_FOLDER/kubernetesOperator.py', '--cfg-path', '/tmp/tmpahowk1sc', '--error-file', '/tmp/tmp9zo6p2h_']
[2021-04-23 17:08:52,340] {standard_task_runner.py:52} INFO - Started process 251 to run task
[2021-04-23 17:08:52,345] {standard_task_runner.py:77} INFO - Job 814: Subtask task-one
[2021-04-23 17:08:52,386] {logging_mixin.py:104} INFO - Running <TaskInstance: ks-3-example_kubernetes_pod.task-one 2019-01-01T00:00:00+00:00 [running]> on host 5af2b1cab26e
[2021-04-23 17:08:52,424] {taskinstance.py:1257} INFO - Exporting the following env vars:
AIRFLOW_CTX_DAG_OWNER=airflow
AIRFLOW_CTX_DAG_ID=ks-3-example_kubernetes_pod
AIRFLOW_CTX_TASK_ID=task-one
AIRFLOW_CTX_EXECUTION_DATE=2019-01-01T00:00:00+00:00
AIRFLOW_CTX_DAG_RUN_ID=scheduled__2019-01-01T00:00:00+00:00
[2021-04-23 17:08:52,426] {taskinstance.py:1455} ERROR - [Errno 2] No such file or directory: '/home/airflow/.kube/config'
Traceback (most recent call last):
  File "/home/airflow/.local/lib/python3.6/site-packages/airflow/models/taskinstance.py", line 1112, in _run_raw_task
    self._prepare_and_execute_task_with_callbacks(context, task)
  File "/home/airflow/.local/lib/python3.6/site-packages/airflow/models/taskinstance.py", line 1285, in _prepare_and_execute_task_with_callbacks
    result = self._execute_task(context, task_copy)
  File "/home/airflow/.local/lib/python3.6/site-packages/airflow/models/taskinstance.py", line 1315, in _execute_task
    result = task_copy.execute(context=context)
  File "/home/airflow/.local/lib/python3.6/site-packages/airflow/providers/cncf/kubernetes/operators/kubernetes_pod.py", line 304, in execute
    config_file=self.config_file,
  File "/home/airflow/.local/lib/python3.6/site-packages/airflow/kubernetes/kube_client.py", line 126, in get_kube_client
    client_conf = _get_kube_config(in_cluster, cluster_context, config_file)
  File "/home/airflow/.local/lib/python3.6/site-packages/airflow/kubernetes/kube_client.py", line 46, in _get_kube_config
    load_kube_config(client_configuration=cfg, config_file=config_file, context=cluster_context)
  File "/home/airflow/.local/lib/python3.6/site-packages/airflow/kubernetes/refresh_config.py", line 121, in load_kube_config
    loader = _get_kube_config_loader_for_yaml_file(config_file, active_context=context, config_persister=None)
  File "/home/airflow/.local/lib/python3.6/site-packages/airflow/kubernetes/refresh_config.py", line 103, in _get_kube_config_loader_for_yaml_file
    with open(filename) as f:
FileNotFoundError: [Errno 2] No such file or directory: '/home/airflow/.kube/config'
[2021-04-23 17:08:52,428] {taskinstance.py:1503} INFO - Marking task as UP_FOR_RETRY. dag_id=ks-3-example_kubernetes_pod, task_id=task-one, execution_date=20190101T000000, start_date=20210423T170852, end_date=20210423T170852
[2021-04-23 17:08:52,481] {local_task_job.py:146} INFO - Task exited with return code 1
