[2021-04-23 17:17:40,961] {taskinstance.py:851} INFO - Dependencies all met for <TaskInstance: ks-4-example_kubernetes_pod.task-one 2019-01-01T00:00:00+00:00 [queued]>
[2021-04-23 17:17:40,979] {taskinstance.py:851} INFO - Dependencies all met for <TaskInstance: ks-4-example_kubernetes_pod.task-one 2019-01-01T00:00:00+00:00 [queued]>
[2021-04-23 17:17:40,981] {taskinstance.py:1042} INFO - 
--------------------------------------------------------------------------------
[2021-04-23 17:17:40,982] {taskinstance.py:1043} INFO - Starting attempt 1 of 2
[2021-04-23 17:17:40,983] {taskinstance.py:1044} INFO - 
--------------------------------------------------------------------------------
[2021-04-23 17:17:40,992] {taskinstance.py:1063} INFO - Executing <Task(KubernetesPodOperator): task-one> on 2019-01-01T00:00:00+00:00
[2021-04-23 17:17:40,996] {standard_task_runner.py:52} INFO - Started process 253 to run task
[2021-04-23 17:17:41,001] {standard_task_runner.py:76} INFO - Running: ['airflow', 'tasks', 'run', 'ks-4-example_kubernetes_pod', 'task-one', '2019-01-01T00:00:00+00:00', '--job-id', '815', '--pool', 'default_pool', '--raw', '--subdir', 'DAGS_FOLDER/kubernetesOperator1.py', '--cfg-path', '/tmp/tmp_e9p10ta', '--error-file', '/tmp/tmph1x8_9jq']
[2021-04-23 17:17:41,002] {standard_task_runner.py:77} INFO - Job 815: Subtask task-one
[2021-04-23 17:17:41,045] {logging_mixin.py:104} INFO - Running <TaskInstance: ks-4-example_kubernetes_pod.task-one 2019-01-01T00:00:00+00:00 [running]> on host 5af2b1cab26e
[2021-04-23 17:17:41,090] {taskinstance.py:1257} INFO - Exporting the following env vars:
AIRFLOW_CTX_DAG_OWNER=airflow
AIRFLOW_CTX_DAG_ID=ks-4-example_kubernetes_pod
AIRFLOW_CTX_TASK_ID=task-one
AIRFLOW_CTX_EXECUTION_DATE=2019-01-01T00:00:00+00:00
AIRFLOW_CTX_DAG_RUN_ID=scheduled__2019-01-01T00:00:00+00:00
[2021-04-23 17:17:41,092] {taskinstance.py:1455} ERROR - [Errno 2] No such file or directory: '/home/airflow/.kube/config'
Traceback (most recent call last):
  File "/home/airflow/.local/lib/python3.6/site-packages/airflow/models/taskinstance.py", line 1112, in _run_raw_task
    self._prepare_and_execute_task_with_callbacks(context, task)
  File "/home/airflow/.local/lib/python3.6/site-packages/airflow/models/taskinstance.py", line 1285, in _prepare_and_execute_task_with_callbacks
    result = self._execute_task(context, task_copy)
  File "/home/airflow/.local/lib/python3.6/site-packages/airflow/models/taskinstance.py", line 1315, in _execute_task
    result = task_copy.execute(context=context)
  File "/home/airflow/.local/lib/python3.6/site-packages/airflow/providers/cncf/kubernetes/operators/kubernetes_pod.py", line 304, in execute
    config_file=self.config_file,
  File "/home/airflow/.local/lib/python3.6/site-packages/airflow/kubernetes/kube_client.py", line 126, in get_kube_client
    client_conf = _get_kube_config(in_cluster, cluster_context, config_file)
  File "/home/airflow/.local/lib/python3.6/site-packages/airflow/kubernetes/kube_client.py", line 46, in _get_kube_config
    load_kube_config(client_configuration=cfg, config_file=config_file, context=cluster_context)
  File "/home/airflow/.local/lib/python3.6/site-packages/airflow/kubernetes/refresh_config.py", line 121, in load_kube_config
    loader = _get_kube_config_loader_for_yaml_file(config_file, active_context=context, config_persister=None)
  File "/home/airflow/.local/lib/python3.6/site-packages/airflow/kubernetes/refresh_config.py", line 103, in _get_kube_config_loader_for_yaml_file
    with open(filename) as f:
FileNotFoundError: [Errno 2] No such file or directory: '/home/airflow/.kube/config'
[2021-04-23 17:17:41,094] {taskinstance.py:1503} INFO - Marking task as UP_FOR_RETRY. dag_id=ks-4-example_kubernetes_pod, task_id=task-one, execution_date=20190101T000000, start_date=20210423T171740, end_date=20210423T171741
[2021-04-23 17:17:41,136] {local_task_job.py:146} INFO - Task exited with return code 1
[2021-04-23 17:28:08,086] {taskinstance.py:851} INFO - Dependencies all met for <TaskInstance: ks-4-example_kubernetes_pod.task-one 2019-01-01T00:00:00+00:00 [queued]>
[2021-04-23 17:28:08,098] {taskinstance.py:851} INFO - Dependencies all met for <TaskInstance: ks-4-example_kubernetes_pod.task-one 2019-01-01T00:00:00+00:00 [queued]>
[2021-04-23 17:28:08,099] {taskinstance.py:1042} INFO - 
--------------------------------------------------------------------------------
[2021-04-23 17:28:08,100] {taskinstance.py:1043} INFO - Starting attempt 1 of 2
[2021-04-23 17:28:08,101] {taskinstance.py:1044} INFO - 
--------------------------------------------------------------------------------
[2021-04-23 17:28:08,107] {taskinstance.py:1063} INFO - Executing <Task(KubernetesPodOperator): task-one> on 2019-01-01T00:00:00+00:00
[2021-04-23 17:28:08,111] {standard_task_runner.py:52} INFO - Started process 51 to run task
[2021-04-23 17:28:08,115] {standard_task_runner.py:76} INFO - Running: ['airflow', 'tasks', 'run', 'ks-4-example_kubernetes_pod', 'task-one', '2019-01-01T00:00:00+00:00', '--job-id', '3', '--pool', 'default_pool', '--raw', '--subdir', 'DAGS_FOLDER/kubernetesOperator1.py', '--cfg-path', '/tmp/tmpzlpybcve', '--error-file', '/tmp/tmp555qw7iw']
[2021-04-23 17:28:08,117] {standard_task_runner.py:77} INFO - Job 3: Subtask task-one
[2021-04-23 17:28:08,158] {logging_mixin.py:104} INFO - Running <TaskInstance: ks-4-example_kubernetes_pod.task-one 2019-01-01T00:00:00+00:00 [running]> on host b0ec5a7abbe9
[2021-04-23 17:28:08,193] {taskinstance.py:1257} INFO - Exporting the following env vars:
AIRFLOW_CTX_DAG_OWNER=airflow
AIRFLOW_CTX_DAG_ID=ks-4-example_kubernetes_pod
AIRFLOW_CTX_TASK_ID=task-one
AIRFLOW_CTX_EXECUTION_DATE=2019-01-01T00:00:00+00:00
AIRFLOW_CTX_DAG_RUN_ID=scheduled__2019-01-01T00:00:00+00:00
[2021-04-23 17:28:08,204] {taskinstance.py:1455} ERROR - Invalid kube-config file. Expected object with name k8s-test in kube-config/contexts list
Traceback (most recent call last):
  File "/home/airflow/.local/lib/python3.6/site-packages/airflow/models/taskinstance.py", line 1112, in _run_raw_task
    self._prepare_and_execute_task_with_callbacks(context, task)
  File "/home/airflow/.local/lib/python3.6/site-packages/airflow/models/taskinstance.py", line 1285, in _prepare_and_execute_task_with_callbacks
    result = self._execute_task(context, task_copy)
  File "/home/airflow/.local/lib/python3.6/site-packages/airflow/models/taskinstance.py", line 1315, in _execute_task
    result = task_copy.execute(context=context)
  File "/home/airflow/.local/lib/python3.6/site-packages/airflow/providers/cncf/kubernetes/operators/kubernetes_pod.py", line 304, in execute
    config_file=self.config_file,
  File "/home/airflow/.local/lib/python3.6/site-packages/airflow/kubernetes/kube_client.py", line 126, in get_kube_client
    client_conf = _get_kube_config(in_cluster, cluster_context, config_file)
  File "/home/airflow/.local/lib/python3.6/site-packages/airflow/kubernetes/kube_client.py", line 46, in _get_kube_config
    load_kube_config(client_configuration=cfg, config_file=config_file, context=cluster_context)
  File "/home/airflow/.local/lib/python3.6/site-packages/airflow/kubernetes/refresh_config.py", line 121, in load_kube_config
    loader = _get_kube_config_loader_for_yaml_file(config_file, active_context=context, config_persister=None)
  File "/home/airflow/.local/lib/python3.6/site-packages/airflow/kubernetes/refresh_config.py", line 107, in _get_kube_config_loader_for_yaml_file
    **kwargs,
  File "/home/airflow/.local/lib/python3.6/site-packages/airflow/kubernetes/refresh_config.py", line 48, in __init__
    KubeConfigLoader.__init__(self, *args, **kwargs)
  File "/home/airflow/.local/lib/python3.6/site-packages/kubernetes/config/kube_config.py", line 197, in __init__
    self.set_active_context(active_context)
  File "/home/airflow/.local/lib/python3.6/site-packages/kubernetes/config/kube_config.py", line 250, in set_active_context
    context_name)
  File "/home/airflow/.local/lib/python3.6/site-packages/kubernetes/config/kube_config.py", line 625, in get_with_name
    'Expected object with name %s in %s list' % (name, self.name))
kubernetes.config.config_exception.ConfigException: Invalid kube-config file. Expected object with name k8s-test in kube-config/contexts list
[2021-04-23 17:28:08,206] {taskinstance.py:1503} INFO - Marking task as UP_FOR_RETRY. dag_id=ks-4-example_kubernetes_pod, task_id=task-one, execution_date=20190101T000000, start_date=20210423T172808, end_date=20210423T172808
[2021-04-23 17:28:08,251] {local_task_job.py:146} INFO - Task exited with return code 1
